Workbook

Sheet INICIO
A1: TABLERO DE ALIANZAS — Heiiu English Academy
A3: Fecha de inicio del contrato | C3: ← la llena gerencia el primer día (dd/mm/aaaa)
A4: Mes de contrato que se revisa (1, 2, 3…) | B4: =IF(B3="","",DATEDIF(B3,TODAY(),"m")+1) | C4: ← por defecto el mes de contrato actual; se puede escribir otro número
A5: Ese mes va del | B5: =IF(B3="","",EDATE(B3,B4-1))
A6: al | B6: =IF(B3="","",EDATE(B3,B4)-1)
A8: CÓMO SE USA
A9: 1. EMPRESAS: cada empresa, fundación o colegio se registra el MISMO DÍA del primer contacto con quien decide. Quien registra primero, es dueño (atribución).
A10: 2. ACTIVIDAD_DIARIA: al cierre de cada día, antes de las 6:00 p. m., una fila: contactos y reuniones con empresas, personas contactadas, citas, inscritos pagados, caja, lo más importante, mañana hago y bloqueos. Es el reporte diario; gerencia lo lee en Drive.
A11: 2b. PLAN_SEMANAL: el lunes antes de las 8:30 a. m. se llena la semana (franjas, lugar, qué) y se comparte con coordinación. Es el registro de la jornada: 42 horas.
A12: 3. TABLERO: se calcula solo. Muestra el mes contra los mínimos, el semáforo y las fechas de decisión. Gerencia lo revisa a diario.
A13: 4. LIQUIDACION: contaduría o gerencia registra lo RECAUDADO en el mes por cada empresa y cada estudiante atribuido; la comisión se calcula sola. Se liquida el día 5 de cada mes y se paga con la nómina.
A14: 5. METAS: tabla pactada en el anexo del contrato (no se cambia sin otrosí).
A15: 6. PRIMERA_SEMANA: plan de arranque y benchmarking de la competencia.
A16: Definiciones: CONTACTO = habló con quien puede firmar (no recepción). REUNIÓN = presentación de 20+ min con quien decide. FIRMA = convenio firmado u orden de plan empresa firmada CON inicial pagada. ACTIVACIÓN = charla, postulación, feria o jornada en una alianza firmada. VENTA FIRMADA = valor total del contrato con inicial pagada (contado o cuotas).

Sheet TABLERO
A1: TABLERO DEL MES
A2: Periodo revisado (desde) | B2: =INICIO!B5 | C2: =INICIO!B6
A3: Mes de contrato | B3: =INICIO!B4
A4: Días hábiles transcurridos / del mes | B4: =IF(B2="","",NETWORKDAYS(B2,MIN(TODAY(),C2))) | C4: =IF(B2="","",NETWORKDAYS(B2,C2))
A5: Avance del mes (%) | B5: =IF(B2="","",B4/C4)
A7: Indicador | B7: Mínimo / meta del mes | C7: Llevamos | D7: Debería llevar hoy | E7: Semáforo
A8: Contactos nuevos con decisor | B8: 40 | C8: =SUMIFS(ACTIVIDAD_DIARIA!$B:$B,ACTIVIDAD_DIARIA!$A:$A,">="&$B$2,ACTIVIDAD_DIARIA!$A:$A,"<="&$C$2) | D8: =IF($B$5="","",ROUND(B8*$B$5,0)) | E8: =IF(OR(B8="",$B$5=""),"",IF(C8>=D8,"VERDE",IF(C8>=D8*0.7,"AMARILLO","ROJO")))
A9: Reuniones | B9: 12 | C9: =SUMIFS(ACTIVIDAD_DIARIA!$C:$C,ACTIVIDAD_DIARIA!$A:$A,">="&$B$2,ACTIVIDAD_DIARIA!$A:$A,"<="&$C$2) | D9: =IF($B$5="","",ROUND(B9*$B$5,0)) | E9: =IF(OR(B9="",$B$5=""),"",IF(C9>=D9,"VERDE",IF(C9>=D9*0.7,"AMARILLO","ROJO")))
A10: Activaciones | B10: =IF($B$3=1,0,IF($B$3=2,2,3)) | C10: =SUMIFS(ACTIVIDAD_DIARIA!$D:$D,ACTIVIDAD_DIARIA!$A:$A,">="&$B$2,ACTIVIDAD_DIARIA!$A:$A,"<="&$C$2) | D10: =IF($B$5="","",ROUND(B10*$B$5,0)) | E10: =IF(OR(B10="",$B$5=""),"",IF(C10>=D10,"VERDE",IF(C10>=D10*0.7,"AMARILLO","ROJO")))
A11: Firmas del mes | B11: 2 | C11: =SUMIFS(ACTIVIDAD_DIARIA!$E:$E,ACTIVIDAD_DIARIA!$A:$A,">="&$B$2,ACTIVIDAD_DIARIA!$A:$A,"<="&$C$2) | D11: =IF($B$5="","",ROUND(B11*$B$5,0)) | E11: =IF(OR(B11="",$B$5=""),"",IF(C11>=D11,"VERDE",IF(C11>=D11*0.7,"AMARILLO","ROJO")))
A12: Ventas firmadas del mes | B12: =IF($B$3="","",IF($B$3<=3,30000000,INDEX(METAS!$E$2:$E$9,MIN(8,ROUNDUP($B$3/3,0))))) | C12: =SUMIFS(ACTIVIDAD_DIARIA!$F:$F,ACTIVIDAD_DIARIA!$A:$A,">="&$B$2,ACTIVIDAD_DIARIA!$A:$A,"<="&$C$2) | D12: =IF($B$5="","",ROUND(B12*$B$5,0)) | E12: =IF(OR(B12="",$B$5=""),"",IF(C12>=D12,"VERDE",IF(C12>=D12*0.7,"AMARILLO","ROJO")))
A13: Firmas acumuladas desde el inicio | B13: =IF($B$3=1,2,IF($B$3=2,4,IF($B$3=3,6,"—"))) | C13: =COUNTIFS(EMPRESAS!$I:$I,"Convenio firmado")+COUNTIFS(EMPRESAS!$I:$I,"Orden pagada")
A15: EMBUDO DEL MES (de cada 10 contactos, ¿cuántos llegan?)
A16: Reuniones / contactos | B16: =IFERROR(C9/C8,"") | C16: referencia: 30% (12 de 40)
A17: Firmas / reuniones | B17: =IFERROR(C11/C9,"") | C17: referencia: 17% (2 de 12)
A19: PIPELINE (lo que viene)
A20: Valor ponderado en negociación | B20: =SUM(EMPRESAS!$V:$V)
A21: Con cierre estimado en los próximos 30 días | B21: =SUMPRODUCT((EMPRESAS!$O$2:$O$401>=TODAY())*(EMPRESAS!$O$2:$O$401<=TODAY()+30)*(EMPRESAS!$V$2:$V$401<>"")*N(+EMPRESAS!$V$2:$V$401))
A22: Convenios firmados sin activar (más de 30 días) | B22: =SUMPRODUCT((EMPRESAS!$I$2:$I$401="Convenio firmado")*(EMPRESAS!$S$2:$S$401="")*(EMPRESAS!$Q$2:$Q$401<>"")*(TODAY()-EMPRESAS!$Q$2:$Q$401>30))
A23: Próximos pasos vencidos | B23: =SUMPRODUCT((EMPRESAS!$U$2:$U$401<>"")*(EMPRESAS!$U$2:$U$401<TODAY())*(EMPRESAS!$I$2:$I$401<>"Perdida")*(EMPRESAS!$I$2:$I$401<>"Orden pagada"))
A25: FECHAS DE DECISIÓN (primer trimestre)
A26: Fecha | B26: Qué se revisa | C26: Si no se cumple
A27: =IF(INICIO!$B$3="","",WORKDAY(INICIO!$B$3-1,10)) | B27: Alerta temprana (≈ día 15): 20 contactos, 6 reuniones, 1 firma | C27: Conversación de ajuste esa misma semana, con plan escrito
A28: =IF(INICIO!$B$3="","",EDATE(INICIO!$B$3,1)-1) | B28: Cierre del mes 1: gestión + 2 firmas (gracia de 5 días para lo firmado) | C28: Sin ingreso mínimo garantizado ese mes; plan de ajuste de una semana
A29: =IF(INICIO!$B$3="","",INICIO!$B$3+49) | B29: DÍA 50: decisión de continuidad ANTES de vencer el período de prueba (2 meses) | C29: Terminar dentro del período de prueba
A30: =IF(INICIO!$B$3="","",EDATE(INICIO!$B$3,3)-1) | B30: Cierre del T1: $90M de meta y 6 firmas acumuladas | C30: Revisión de continuidad y del plan del T2

Sheet EMPRESAS
A1: Empresa / fundación / colegio | B1: Tipo | C1: Sector | D1: Decisor (nombre) | E1: Cargo | F1: Teléfono / correo | G1: Fecha 1er contacto con decisor | H1: Canal (llamada, visita, feria, referido) | I1: Estado | J1: Fecha reunión | K1: Oferta | L1: Cupos / estudiantes estimados | M1: Valor estimado | N1: Probabilidad | O1: Fecha estimada de cierre | P1: Valor firmado | Q1: Fecha de firma | R1: Inicial pagada (Sí/No) | S1: Fecha 1a activación | T1: Próximo paso | U1: Fecha próximo paso | V1: Valor ponderado
V2: =IF(OR(M2="",N2=""),"",IF(OR(I2="Orden pagada",I2="Convenio firmado",I2="Perdida"),"",M2*N2))
V3: =IF(OR(M3="",N3=""),"",IF(OR(I3="Orden pagada",I3="Convenio firmado",I3="Perdida"),"",M3*N3))
V4: =IF(OR(M4="",N4=""),"",IF(OR(I4="Orden pagada",I4="Convenio firmado",I4="Perdida"),"",M4*N4))
V5: =IF(OR(M5="",N5=""),"",IF(OR(I5="Orden pagada",I5="Convenio firmado",I5="Perdida"),"",M5*N5))
V6: =IF(OR(M6="",N6=""),"",IF(OR(I6="Orden pagada",I6="Convenio firmado",I6="Perdida"),"",M6*N6))
V7: =IF(OR(M7="",N7=""),"",IF(OR(I7="Orden pagada",I7="Convenio firmado",I7="Perdida"),"",M7*N7))
V8: =IF(OR(M8="",N8=""),"",IF(OR(I8="Orden pagada",I8="Convenio firmado",I8="Perdida"),"",M8*N8))
V9: =IF(OR(M9="",N9=""),"",IF(OR(I9="Orden pagada",I9="Convenio firmado",I9="Perdida"),"",M9*N9))
V10: =IF(OR(M10="",N10=""),"",IF(OR(I10="Orden pagada",I10="Convenio firmado",I10="Perdida"),"",M10*N10))
V11: =IF(OR(M11="",N11=""),"",IF(OR(I11="Orden pagada",I11="Convenio firmado",I11="Perdida"),"",M11*N11))
V12: =IF(OR(M12="",N12=""),"",IF(OR(I12="Orden pagada",I12="Convenio firmado",I12="Perdida"),"",M12*N12))
V13: =IF(OR(M13="",N13=""),"",IF(OR(I13="Orden pagada",I13="Convenio firmado",I13="Perdida"),"",M13*N13))
... V401: =IF(OR(M401="",N401=""),"",IF(OR(I401="Orden pagada",I401="Convenio firmado",I401="Perdida"),"",M401*N401))

Sheet ACTIVIDAD_DIARIA
A1: Fecha | B1: Contactos nuevos con decisor | C1: Reuniones hechas | D1: Activaciones | E1: Firmas (convenio u orden pagada) | F1: Ventas firmadas del día ($) | G1: Personas contactadas (referidos, conocidos, afiliados) | H1: Citas con personas hechas | I1: Inscritos pagados hoy (personas) | J1: Caja recibida hoy ($) | K1: Lo más importante de hoy | L1: Mañana hago (empresas / reuniones / citas) | M1: Bloqueos / lo que necesito de gerencia | O1: Se llena al cierre de cada día, antes de las 6:00 p. m., una fila por día (también los días sin resultados: se escribe 0). Gerencia la lee en Drive sin pedirla.

Sheet PLAN_SEMANAL
A1: PLAN DE ORGANIZACIÓN DEL TIEMPO — semana a semana
A2: Se llena el lunes antes de las 8:30 a. m. y se comparte con coordinación: es el registro de la jornada (calidad y seguridad en el trabajo). 42 horas a la semana, en franjas concretas con lugar. Si la semana cambia, se corrige aquí el mismo día. Contacto con clientes solo de lunes a viernes de 7:00 a. m. a 7:00 p. m. y sábados de 8:00 a. m. a 3:00 p. m.; nunca domingos ni festivos.
A4: Semana 1 · del | C4: Enviado a coordinación:
A5: Día | B5: Mañana de | C5: a | D5: Dónde | E5: Qué (empresas, reuniones, citas, oficina) | F5: Tarde de | G5: a | H5: Dónde | I5: Qué | J5: Horas | K5: Observaciones / cambios
A6: Lunes | J6: =(IF(AND(B6<>"",C6<>""),C6-B6,0)+IF(AND(F6<>"",G6<>""),G6-F6,0))*24
A7: Martes | J7: =(IF(AND(B7<>"",C7<>""),C7-B7,0)+IF(AND(F7<>"",G7<>""),G7-F7,0))*24
A8: Miércoles | J8: =(IF(AND(B8<>"",C8<>""),C8-B8,0)+IF(AND(F8<>"",G8<>""),G8-F8,0))*24
A9: Jueves | J9: =(IF(AND(B9<>"",C9<>""),C9-B9,0)+IF(AND(F9<>"",G9<>""),G9-F9,0))*24
A10: Viernes | J10: =(IF(AND(B10<>"",C10<>""),C10-B10,0)+IF(AND(F10<>"",G10<>""),G10-F10,0))*24
A11: Sábado | J11: =(IF(AND(B11<>"",C11<>""),C11-B11,0)+IF(AND(F11<>"",G11<>""),G11-F11,0))*24
I12: Total de la semana | J12: =SUM(J6:J11) | K12: =IF(J12=0,"",IF(J12<42,"Faltan "&TEXT(42-J12,"0.0")&" horas para las 42",IF(J12>42,"Pasa de 42: ajustar","Cumple 42 horas")))
A14: Semana 2 · del | C14: Enviado a coordinación:
A15: Día | B15: Mañana de | C15: a | D15: Dónde | E15: Qué (empresas, reuniones, citas, oficina) | F15: Tarde de | G15: a | H15: Dónde | I15: Qué | J15: Horas | K15: Observaciones / cambios
A16: Lunes | J16: =(IF(AND(B16<>"",C16<>""),C16-B16,0)+IF(AND(F16<>"",G16<>""),G16-F16,0))*24
A17: Martes | J17: =(IF(AND(B17<>"",C17<>""),C17-B17,0)+IF(AND(F17<>"",G17<>""),G17-F17,0))*24
A18: Miércoles | J18: =(IF(AND(B18<>"",C18<>""),C18-B18,0)+IF(AND(F18<>"",G18<>""),G18-F18,0))*24
A19: Jueves | J19: =(IF(AND(B19<>"",C19<>""),C19-B19,0)+IF(AND(F19<>"",G19<>""),G19-F19,0))*24
A20: Viernes | J20: =(IF(AND(B20<>"",C20<>""),C20-B20,0)+IF(AND(F20<>"",G20<>""),G20-F20,0))*24
A21: Sábado | J21: =(IF(AND(B21<>"",C21<>""),C21-B21,0)+IF(AND(F21<>"",G21<>""),G21-F21,0))*24
I22: Total de la semana | J22: =SUM(J16:J21) | K22: =IF(J22=0,"",IF(J22<42,"Faltan "&TEXT(42-J22,"0.0")&" horas para las 42",IF(J22>42,"Pasa de 42: ajustar","Cumple 42 horas")))
A24: Semana 3 · del | C24: Enviado a coordinación:
A25: Día | B25: Mañana de | C25: a | D25: Dónde | E25: Qué (empresas, reuniones, citas, oficina) | F25: Tarde de | G25: a | H25: Dónde | I25: Qué | J25: Horas | K25: Observaciones / cambios
A26: Lunes | J26: =(IF(AND(B26<>"",C26<>""),C26-B26,0)+IF(AND(F26<>"",G26<>""),G26-F26,0))*24
A27: Martes | J27: =(IF(AND(B27<>"",C27<>""),C27-B27,0)+IF(AND(F27<>"",G27<>""),G27-F27,0))*24
A28: Miércoles | J28: =(IF(AND(B28<>"",C28<>""),C28-B28,0)+IF(AND(F28<>"",G28<>""),G28-F28,0))*24
A29: Jueves | J29: =(IF(AND(B29<>"",C29<>""),C29-B29,0)+IF(AND(F29<>"",G29<>""),G29-F29,0))*24
A30: Viernes | J30: =(IF(AND(B30<>"",C30<>""),C30-B30,0)+IF(AND(F30<>"",G30<>""),G30-F30,0))*24
A31: Sábado | J31: =(IF(AND(B31<>"",C31<>""),C31-B31,0)+IF(AND(F31<>"",G31<>""),G31-F31,0))*24
I32: Total de la semana | J32: =SUM(J26:J31) | K32: =IF(J32=0,"",IF(J32<42,"Faltan "&TEXT(42-J32,"0.0")&" horas para las 42",IF(J32>42,"Pasa de 42: ajustar","Cumple 42 horas")))
A34: Semana 4 · del | C34: Enviado a coordinación:
A35: Día | B35: Mañana de | C35: a | D35: Dónde | E35: Qué (empresas, reuniones, citas, oficina) | F35: Tarde de | G35: a | H35: Dónde | I35: Qué | J35: Horas | K35: Observaciones / cambios
A36: Lunes | J36: =(IF(AND(B36<>"",C36<>""),C36-B36,0)+IF(AND(F36<>"",G36<>""),G36-F36,0))*24
A37: Martes | J37: =(IF(AND(B37<>"",C37<>""),C37-B37,0)+IF(AND(F37<>"",G37<>""),G37-F37,0))*24
A38: Miércoles | J38: =(IF(AND(B38<>"",C38<>""),C38-B38,0)+IF(AND(F38<>"",G38<>""),G38-F38,0))*24
A39: Jueves | J39: =(IF(AND(B39<>"",C39<>""),C39-B39,0)+IF(AND(F39<>"",G39<>""),G39-F39,0))*24
A40: Viernes | J40: =(IF(AND(B40<>"",C40<>""),C40-B40,0)+IF(AND(F40<>"",G40<>""),G40-F40,0))*24
A41: Sábado | J41: =(IF(AND(B41<>"",C41<>""),C41-B41,0)+IF(AND(F41<>"",G41<>""),G41-F41,0))*24
I42: Total de la semana | J42: =SUM(J36:J41) | K42: =IF(J42=0,"",IF(J42<42,"Faltan "&TEXT(42-J42,"0.0")&" horas para las 42",IF(J42>42,"Pasa de 42: ajustar","Cumple 42 horas")))
A44: Semana 5 · del | C44: Enviado a coordinación:
A45: Día | B45: Mañana de | C45: a | D45: Dónde | E45: Qué (empresas, reuniones, citas, oficina) | F45: Tarde de | G45: a | H45: Dónde | I45: Qué | J45: Horas | K45: Observaciones / cambios
...

Sheet METAS
A1: Trimestre | B1: Meses de contrato desde | C1: hasta | D1: Meta del trimestre (ventas firmadas) | E1: Meta al mes (referencia) | F1: Programas completos al mes (≈) | G1: Básico
A2: T1 | B2: 1 | C2: 3 | D2: 90000000 | E2: 30000000 | F2: 6 + 1 Arranque | G2: SMMLV + auxilio
A3: T2 | B3: 4 | C3: 6 | D3: 144000000 | E3: 48000000 | F3: 10 | G3: SMMLV + auxilio
A4: T3 | B4: 7 | C4: 9 | D4: 198000000 | E4: 66000000 | F4: 14 | G4: SMMLV + $550.000 + auxilio (si cumple)
A5: T4 | B5: 10 | C5: 12 | D5: 234000000 | E5: 78000000 | F5: 16 | G5: SMMLV + $550.000 + auxilio (si cumple)
A6: T5 | B6: 13 | C6: 15 | D6: 252000000 | E6: 84000000 | F6: 18 | G6: SMMLV + $850.000 + auxilio (si cumple)
A7: T6 | B7: 16 | C7: 18 | D7: 276000000 | E7: 92000000 | F7: 19 | G7: SMMLV + $850.000 + auxilio (si cumple)
A8: T7 | B8: 19 | C8: 21 | D8: 300000000 | E8: 100000000 | F8: 21 | G8: SMMLV + $850.000 + auxilio (si cumple)
A9: T8 | B9: 22 | C9: 24 | D9: 324000000 | E9: 108000000 | F9: 23 | G9: SMMLV + $850.000 + auxilio (si cumple)
A11: Desde T9: la meta del trimestre anterior + 2,5% (salvo otrosí). Acelerador: 10% hasta la meta, 15% del 100 al 130%, 20% sobre 130% (trimestres con 2+ empresas nuevas firmadas).
A13: Mínimos de gestión (cada mes)
A14: Mes de contrato | B14: Contactos con decisor | C14: Reuniones | D14: Activaciones | E14: Firmas acumuladas | F14: Meta de ventas del mes
A15: 1 | B15: 40 | C15: 12 | D15: 0 | E15: 2 | F15: 30000000
A16: 2 | B16: 40 | C16: 12 | D16: 2 | E16: 4 | F16: 30000000
A17: 3 | B17: 40 | C17: 12 | D17: 3 | E17: 6 | F17: 30000000
A18: 4+ | B18: 40 | C18: 12 | D18: 1 por alianza por trimestre | E18: — | F18: según trimestre

Sheet LIQUIDACION
A1: LIQUIDACIÓN DE COMISIONES — sobre lo RECAUDADO (no sobre lo firmado)
A2: Mes liquidado (primer día)
A3: Básico del mes (SMMLV + auxilio vigente) | B3: 2000000
A4: ¿Cumplió gestión y firmas? (meses 1-3) | B4: Sí
A6: Empresa o estudiante | B6: Tipo de comisión | C6: Fecha de firma de la matrícula / orden | D6: Recaudado en el mes ($) | E6: Meses desde la firma | F6: % que aplica | G6: Comisión ($) | H6: Soporte (recibo / factura) | I6: Nota
E7: =IF(OR(C7="",$B$2=""),"",DATEDIF(C7,EOMONTH($B$2,0),"m")+1) | F7: =IF(B7="","",IF(LEFT(B7,4)="Plan",IF(E7<=12,0.10,0),IF(LEFT(B7,7)="Cartera",IF(E7<=12,0.06,IF(E7<=24,0.03,0)),"tarifa asesora"))) | G7: =IF(OR(D7="",F7=""),"",IF(ISNUMBER(F7),D7*F7,"")) | I7: Cierre de apoyo: escribir la comisión de asesora a mano en G. El acelerador (15% / 20%) se liquida al cierre del trimestre aparte.
E8: =IF(OR(C8="",$B$2=""),"",DATEDIF(C8,EOMONTH($B$2,0),"m")+1) | F8: =IF(B8="","",IF(LEFT(B8,4)="Plan",IF(E8<=12,0.10,0),IF(LEFT(B8,7)="Cartera",IF(E8<=12,0.06,IF(E8<=24,0.03,0)),"tarifa asesora"))) | G8: =IF(OR(D8="",F8=""),"",IF(ISNUMBER(F8),D8*F8,""))
E9: =IF(OR(C9="",$B$2=""),"",DATEDIF(C9,EOMONTH($B$2,0),"m")+1) | F9: =IF(B9="","",IF(LEFT(B9,4)="Plan",IF(E9<=12,0.10,0),IF(LEFT(B9,7)="Cartera",IF(E9<=12,0.06,IF(E9<=24,0.03,0)),"tarifa asesora"))) | G9: =IF(OR(D9="",F9=""),"",IF(ISNUMBER(F9),D9*F9,""))
E10: =IF(OR(C10="",$B$2=""),"",DATEDIF(C10,EOMONTH($B$2,0),"m")+1) | F10: =IF(B10="","",IF(LEFT(B10,4)="Plan",IF(E10<=12,0.10,0),IF(LEFT(B10,7)="Cartera",IF(E10<=12,0.06,IF(E10<=24,0.03,0)),"tarifa asesora"))) | G10: =IF(OR(D10="",F10=""),"",IF(ISNUMBER(F10),D10*F10,""))
E11: =IF(OR(C11="",$B$2=""),"",DATEDIF(C11,EOMONTH($B$2,0),"m")+1) | F11: =IF(B11="","",IF(LEFT(B11,4)="Plan",IF(E11<=12,0.10,0),IF(LEFT(B11,7)="Cartera",IF(E11<=12,0.06,IF(E11<=24,0.03,0)),"tarifa asesora"))) | G11: =IF(OR(D11="",F11=""),"",IF(ISNUMBER(F11),D11*F11,""))
E12: =IF(OR(C12="",$B$2=""),"",DATEDIF(C12,EOMONTH($B$2,0),"m")+1) | F12: =IF(B12="","",IF(LEFT(B12,4)="Plan",IF(E12<=12,0.10,0),IF(LEFT(B12,7)="Cartera",IF(E12<=12,0.06,IF(E12<=24,0.03,0)),"tarifa asesora"))) | G12: =IF(OR(D12="",F12=""),"",IF(ISNUMBER(F12),D12*F12,""))
E13: =IF(OR(C13="",$B$2=""),"",DATEDIF(C13,EOMONTH($B$2,0),"m")+1) | F13: =IF(B13="","",IF(LEFT(B13,4)="Plan",IF(E13<=12,0.10,0),IF(LEFT(B13,7)="Cartera",IF(E13<=12,0.06,IF(E13<=24,0.03,0)),"tarifa asesora"))) | G13: =IF(OR(D13="",F13=""),"",IF(ISNUMBER(F13),D13*F13,""))
E14: =IF(OR(C14="",$B$2=""),"",DATEDIF(C14,EOMONTH($B$2,0),"m")+1) | F14: =IF(B14="","",IF(LEFT(B14,4)="Plan",IF(E14<=12,0.10,0),IF(LEFT(B14,7)="Cartera",IF(E14<=12,0.06,IF(E14<=24,0.03,0)),"tarifa asesora"))) | G14: =IF(OR(D14="",F14=""),"",IF(ISNUMBER(F14),D14*F14,""))
E15: =IF(OR(C15="",$B$2=""),"",DATEDIF(C15,EOMONTH($B$2,0),"m")+1) | F15: =IF(B15="","",IF(LEFT(B15,4)="Plan",IF(E15<=12,0.10,0),IF(LEFT(B15,7)="Cartera",IF(E15<=12,0.06,IF(E15<=24,0.03,0)),"tarifa asesora"))) | G15: =IF(OR(D15="",F15=""),"",IF(ISNUMBER(F15),D15*F15,""))
E16: =IF(OR(C16="",$B$2=""),"",DATEDIF(C16,EOMONTH($B$2,0),"m")+1) | F16: =IF(B16="","",IF(LEFT(B16,4)="Plan",IF(E16<=12,0.10,0),IF(LEFT(B16,7)="Cartera",IF(E16<=12,0.06,IF(E16<=24,0.03,0)),"tarifa asesora"))) | G16: =IF(OR(D16="",F16=""),"",IF(ISNUMBER(F16),D16*F16,""))
E17: =IF(OR(C17="",$B$2=""),"",DATEDIF(C17,EOMONTH($B$2,0),"m")+1) | F17: =IF(B17="","",IF(LEFT(B17,4)="Plan",IF(E17<=12,0.10,0),IF(LEFT(B17,7)="Cartera",IF(E17<=12,0.06,IF(E17<=24,0.03,0)),"tarifa asesora"))) | G17: =IF(OR(D17="",F17=""),"",IF(ISNUMBER(F17),D17*F17,""))
E18: =IF(OR(C18="",$B$2=""),"",DATEDIF(C18,EOMONTH($B$2,0),"m")+1) | F18: =IF(B18="","",IF(LEFT(B18,4)="Plan",IF(E18<=12,0.10,0),IF(LEFT(B18,7)="Cartera",IF(E18<=12,0.06,IF(E18<=24,0.03,0)),"tarifa asesora"))) | G18: =IF(OR(D18="",F18=""),"",IF(ISNUMBER(F18),D18*F18,""))
E19: =IF(OR(C19="",$B$2=""),"",DATEDIF(C19,EOMONTH($B$2,0),"m")+1) | F19: =IF(B19="","",IF(LEFT(B19,4)="Plan",IF(E19<=12,0.10,0),IF(LEFT(B19,7)="Cartera",IF(E19<=12,0.06,IF(E19<=24,0.03,0)),"tarifa asesora"))) | G19: =IF(OR(D19="",F19=""),"",IF(ISNUMBER(F19),D19*F19,""))
... E306: =IF(OR(C306="",$B$2=""),"",DATEDIF(C306,EOMONTH($B$2,0),"m")+1) | F306: =IF(B306="","",IF(LEFT(B306,4)="Plan",IF(E306<=12,0.10,0),IF(LEFT(B306,7)="Cartera",IF(E306<=12,0.06,IF(E306<=24,0.03,0)),"tarifa asesora"))) | G306: =IF(OR(D306="",F306=""),"",IF(ISNUMBER(F306),D306*F306,""))
A309: Total comisiones del mes | G309: =SUM(G7:G306)
A310: Básico | G310: =B3
A311: Complemento por ingreso mínimo garantizado ($3.500.000, meses 1-3 si cumplió) | G311: =IF(B4="Sí",MAX(0,3500000-(G309+G310)),0)
A312: TOTAL A PAGAR (antes de deducciones de ley) | G312: =G309+G310+G311

Sheet PRIMERA_SEMANA
A1: PRIMERA SEMANA — arranque
A3: Día | B3: Qué | C3: Entregable | D3: Hecho (Sí/No)
A4: 1 | B4: Inducción: producto, Fondo de Becas, convenio, orden de plan empresa, tarifa por volumen, módulo de graduación, garantía. | C4: Kit leído y preguntas resueltas
A5: 1-2 | B5: Benchmarking de 7 academias (abajo): llamada o visita como cliente, web y biblioteca de anuncios de Meta. | C5: Tabla de benchmarking completa
A6: 2-3 | B6: Lista de 100 empresas, fundaciones y colegios objetivo, con decisor identificado, cargadas en EMPRESAS. | C6: 100 filas en EMPRESAS
A7: 3 | B7: Simulación de presentación con gerencia (gerente de una empresa de 40 empleados). | C7: Presentación aprobada
A8: 4-5 | B8: Primeros contactos con decisor y primeras reuniones agendadas. | C8: ≥ 10 contactos y ≥ 3 reuniones agendadas
A9: 5 | B9: Formato de captura de datos para ferias con autorización de tratamiento de datos (Ley 1581). | C9: Formato listo
A12: BENCHMARKING DE LA COMPETENCIA
A13: Academia | B13: ¿Garantía de aprendizaje por escrito? | C13: Oferta a empresas y precios | D13: Convenio con cajas de compensación | E13: Certificaciones | F13: Qué prometen en sus anuncios | G13: Fuente y fecha
A14: Smart
A15: Colombo Americano
A16: Best English
A17: Praxis
A18: Lingui
A19: Berlitz
A20: Celai
A22: Regla: hasta completar esta tabla, con empresas NO se dice "la única academia que la firma"; se dice "garantía de aprendizaje por escrito, sin letra pequeña".
